<?xml version="1.0" ?>
<!-- =================================================================================== -->
<!-- |    This document was autogenerated by xacro from panda_arm_hand.urdf.xacro      | -->
<!-- |    EDITING THIS FILE BY HAND IS NOT RECOMMENDED                                 | -->
<!-- =================================================================================== -->
<robot name="panda" xmlns:xacro="http://www.ros.org/wiki/xacro">
  <link name="panda_link0">
  	<inertial>
      <origin rpy="0 0 0" xyz="0 0 0"/>
       <mass value="0.0"/>
       <inertia ixx="0" ixy="0" ixz="0" iyy="0" iyz="0" izz="0"/>
    </inertial>
    <visual>
      <geometry>
        <mesh filename="/meshes/collision/link0.obj"/>
      </geometry>
      <material name="panda_white">
    		<color rgba="1. 1. 1. 1."/>
  		</material>
    </visual>
    <collision>
      <geometry>
        <mesh filename="/meshes/collision/link0.obj"/>
      </geometry>
    </collision>
  </link>
  <link name="panda_link1">
  	<inertial>
      <origin rpy="0 0 0" xyz="0.00033 -0.02204 -0.04762"/>
       <mass value="2.7907"/>
       <inertia ixx="0.01564782655" ixy="0.00000531236" ixz="-0.00003676721" iyy="0.01439883526" iyz="-0.00248480843" izz="0.00500443991"/>
    </inertial>
    <visual>
      <geometry>
        <mesh filename="/meshes/visual/link1.obj"/>
      </geometry>
      <material name="panda_white"/>
    </visual>
    <collision>
      <geometry>
        <mesh filename="/meshes/collision/link1.obj"/>
      </geometry>
    </collision>
  </link>
  <link name="panda_link2">
  	<inertial>
      <origin rpy="0 0 0" xyz="0.00038 -0.09211 0.01908"/>
       <mass value="2.5420"/>
       <inertia ixx="0.01662427728" ixy="0.00003086077" ixz="0.00000835940" iyy="0.00462501261" iyz="0.00355899830" izz="0.01545124526"/>
    </inertial>
    <visual>
      <geometry>
        <mesh filename="/meshes/visual/link2.obj"/>
      </geometry>
      <material name="panda_white"/>
    </visual>
    <collision>
      <geometry>
        <mesh filename="/meshes/collision/link2.obj"/>
      </geometry>
    </collision>
  </link>
  <link name="panda_link3">
	  <inertial>
      <origin rpy="0 0 0" xyz="0.05152 0.01696 -0.02971"/>
       <mass value="2.2513"/>
       <inertia ixx="0.00631741992" ixy="0.00097309955" ixz="0.00292525834" iyy="0.00866285493" iyz="0.00093469224" izz="0.00657804051"/>
    </inertial>
    <visual>
      <geometry>
        <mesh filename="/meshes/visual/link3.obj"/>
      </geometry>
      <material name="panda_red">
    		<color rgba="1. 1. 1. 1."/>
  		</material>
    </visual>
    <collision>
      <geometry>
        <mesh filename="/meshes/collision/link3.obj"/>
      </geometry>
    </collision>
  </link>
  <link name="panda_link4">
  	<inertial>
      <origin rpy="0 0 0" xyz="-0.05113 0.05825 0.01698"/>
       <mass value="2.2037"/>
       <inertia ixx="0.0156" ixy="-0.0" ixz="0.0" iyy="0.01439" iyz="-0.0024" izz="0.005"/>
    </inertial>
    <visual>
      <geometry>
        <mesh filename="/meshes/visual/link4.obj"/>
      </geometry>
      <material name="panda_white"/>
    </visual>
    <collision>
      <geometry>
        <mesh filename="/meshes/collision/link4.obj"/>
      </geometry>
    </collision>
  </link>
  <link name="panda_link5">
  	<inertial>
      <origin rpy="0 0 0" xyz="-0.00005 0.03730 -0.09280"/>
       <mass value="2.2855"/>
       <inertia ixx="0.02297014781" ixy="-0.00000949345" ixz="-0.00002063156" iyy="0.02095060919" iyz="0.00382345782" izz="0.00430606551"/>
    </inertial>
    <visual>
      <geometry>
        <mesh filename="/meshes/visual/link5.obj"/>
      </geometry>
      <material name="panda_white"/>
    </visual>
    <!--
    <collision>
      <geometry>
        <mesh filename="/meshes/collision/link5.obj"/>
      </geometry>
    </collision>
    -->
    <collision>
      <origin rpy="0.0 0.0 0.0" xyz="0.0 0.0 -0.22"/>
      <geometry>
        <cylinder length="0.07" radius="0.055"/>
      </geometry>
    </collision>
    <collision>
      <origin rpy="-1.57079632 0.0 0.0" xyz="0.0 0.06 0"/>
      <geometry>
        <cylinder length="0.08" radius="0.05"/>
      </geometry>
    </collision>
    <collision>
      <origin rpy="0.0 0.0 0.0" xyz="0.01 0.08 -0.14"/>
      <geometry>
        <sphere radius="0.022"/>
      </geometry>
    </collision>
    <collision>
      <origin rpy="0.0 0.0 0.0" xyz="0.01 0.085 -0.11"/>
      <geometry>
        <sphere radius="0.022"/>
      </geometry>
    </collision>
    <collision>
      <origin rpy="0.0 0.0 0.0" xyz="0.01 0.09 -0.08"/>
      <geometry>
        <sphere radius="0.022"/>
      </geometry>
    </collision>
    <collision>
      <origin rpy="0.0 0.0 0.0" xyz="0.01 0.095 -0.05"/>
      <geometry>
        <sphere radius="0.022"/>
      </geometry>
    </collision>
    <collision>
      <origin rpy="0.0 0.0 0.0" xyz="-0.01 0.08 -0.14"/>
      <geometry>
        <sphere radius="0.022"/>
      </geometry>
    </collision>
    <collision>
      <origin rpy="0.0 0.0 0.0" xyz="-0.01 0.085 -0.11"/>
      <geometry>
        <sphere radius="0.022"/>
      </geometry>
    </collision>
    <collision>
      <origin rpy="0.0 0.0 0.0" xyz="-0.01 0.09 -0.08"/>
      <geometry>
        <sphere radius="0.022"/>
      </geometry>
    </collision>
    <collision>
      <origin rpy="0.0 0.0 0.0" xyz="-0.01 0.095 -0.05"/>
      <geometry>
        <sphere radius="0.022"/>
      </geometry>
    </collision>

  </link>

  <link name="panda_link6">
  	<inertial>
      <origin rpy="0 0 0" xyz="0.06572 -0.00371 0.00153"/>
       <mass value="1.353"/>
       <inertia ixx="0.00087964522" ixy="-0.00021487814" ixz="-0.00011911662" iyy="0.00277796968" iyz="0.00001274322" izz="0.00286701969"/>
    </inertial>
    <visual>
      <geometry>
        <mesh filename="package://meshes/visual/link6.obj"/>
      </geometry>
      <material name="panda_white"/>
    </visual>
    <collision>
      <geometry>
        <mesh filename="package://meshes/collision/link6.obj"/>
      </geometry>
    </collision>
  </link>

  <link name="panda_link7">
  	<inertial>
      <origin rpy="0 0 0" xyz="0.00089 -0.00044 0.05491"/>
       <mass value="0.35973"/>
       <inertia ixx="0.00019541063" ixy="0.00000165231" ixz="0.00000148826" iyy="0.00019210361" iyz="-0.00000131132" izz="0.00017936256"/>
    </inertial>
    <visual>
      <geometry>
        <mesh filename="package://meshes/collision/link7.obj"/>
      </geometry>
      <material name="panda_white"/>
    </visual>
    <collision>
      <geometry>
        <mesh filename="package://meshes/collision/link7.obj"/>
      </geometry>
    </collision>
  </link>
  
  <link name="panda_flange">
    <inertial>
      <origin rpy="0 0 0" xyz="0 0 0"/>
       <mass value="0"/>
       <inertia ixx="0.0" ixy="0.0" ixz="0.0" iyy="0.0" iyz="0.0" izz="0.0"/>
    </inertial>
  </link>

  <joint name="panda_joint1" type="revolute">
    <safety_controller k_position="100.0" k_velocity="40.0" soft_lower_limit="-2.8973" soft_upper_limit="2.8973"/>
    <origin rpy="0 0 0" xyz="0 0 0.333"/>
    <parent link="panda_link0"/>
    <child link="panda_link1"/>
    <axis xyz="0 0 1"/>
    <limit effort="87" lower="-2.8973" upper="2.8973" velocity="2.1750"/>
  </joint>
  <joint name="panda_joint2" type="revolute">
    <safety_controller k_position="100.0" k_velocity="40.0" soft_lower_limit="-1.7628" soft_upper_limit="1.7628"/>
    <origin rpy="-1.57079632679 0 0" xyz="0 0 0"/>
    <parent link="panda_link1"/>
    <child link="panda_link2"/>
    <axis xyz="0 0 1"/>
    <limit effort="87" lower="-1.7628" upper="1.7628" velocity="2.1750"/>
  </joint>
  <joint name="panda_joint3" type="revolute">
    <safety_controller k_position="100.0" k_velocity="40.0" soft_lower_limit="-2.8973" soft_upper_limit="2.8973"/>
    <origin rpy="1.57079632679 0 0" xyz="0 -0.316 0"/>
    <parent link="panda_link2"/>
    <child link="panda_link3"/>
    <axis xyz="0 0 1"/>
    <limit effort="87" lower="-2.8973" upper="2.8973" velocity="2.1750"/>
  </joint>
  <joint name="panda_joint4" type="revolute">
    <safety_controller k_position="100.0" k_velocity="40.0" soft_lower_limit="-3.0718" soft_upper_limit="-0.0698"/>
    <origin rpy="1.57079632679 0 0" xyz="0.0825 0 0"/>
    <parent link="panda_link3"/>
    <child link="panda_link4"/>
    <axis xyz="0 0 1"/>
    <limit effort="87" lower="-3.0718" upper="-0.0698" velocity="2.1750"/>
  </joint>
  <joint name="panda_joint5" type="revolute">
    <safety_controller k_position="100.0" k_velocity="40.0" soft_lower_limit="-2.8973" soft_upper_limit="2.8973"/>
    <origin rpy="-1.57079632679 0 0" xyz="-0.0825 0.384 0"/>
    <parent link="panda_link4"/>
    <child link="panda_link5"/>
    <axis xyz="0 0 1"/>
    <limit effort="12" lower="-2.8973" upper="2.8973" velocity="2.6100"/>
  </joint>
  <joint name="panda_joint6" type="revolute">
    <safety_controller k_position="100.0" k_velocity="40.0" soft_lower_limit="-0.0175" soft_upper_limit="3.7525"/>
    <origin rpy="1.57079632679 0 0" xyz="0 0 0"/>
    <parent link="panda_link5"/>
    <child link="panda_link6"/>
    <axis xyz="0 0 1"/>
    <limit effort="12" lower="-0.0175" upper="3.7525" velocity="2.6100"/>
  </joint>
  <joint name="panda_joint7" type="revolute">
    <safety_controller k_position="100.0" k_velocity="40.0" soft_lower_limit="-2.8973" soft_upper_limit="2.8973"/>
    <origin rpy="1.57079632679 0 0" xyz="0.088 0 0"/>
    <parent link="panda_link6"/>
    <child link="panda_link7"/>
    <axis xyz="0 0 1"/>
    <limit effort="12" lower="-2.8973" upper="2.8973" velocity="2.6100"/>
  </joint>

  <joint name="panda_joint8" type="fixed">
    <origin rpy="0 0 0" xyz="0 0 0.1070"/>
    <parent link="panda_link7"/>
    <child link="panda_flange"/>
  </joint>
  
</robot>
